[2025-07-15T03:56:02.035+0000] {local_task_job_runner.py:120} INFO - ::group::Pre task execution logs
[2025-07-15T03:56:02.060+0000] {taskinstance.py:2076} INFO - Dependencies all met for dep_context=non-requeueable deps ti=<TaskInstance: test_first_run_and_custom_date.one_time_setup_with_pre_execute scheduled__2025-07-11T17:00:00+00:00 [queued]>
[2025-07-15T03:56:02.066+0000] {taskinstance.py:2076} INFO - Dependencies all met for dep_context=requeueable deps ti=<TaskInstance: test_first_run_and_custom_date.one_time_setup_with_pre_execute scheduled__2025-07-11T17:00:00+00:00 [queued]>
[2025-07-15T03:56:02.067+0000] {taskinstance.py:2306} INFO - Starting attempt 1 of 1
[2025-07-15T03:56:02.074+0000] {taskinstance.py:2330} INFO - Executing <Task(BashOperator): one_time_setup_with_pre_execute> on 2025-07-11 17:00:00+00:00
[2025-07-15T03:56:02.078+0000] {standard_task_runner.py:63} INFO - Started process 1165 to run task
[2025-07-15T03:56:02.080+0000] {standard_task_runner.py:90} INFO - Running: ['***', 'tasks', 'run', 'test_first_run_and_custom_date', 'one_time_setup_with_pre_execute', 'scheduled__2025-07-11T17:00:00+00:00', '--job-id', '2', '--raw', '--subdir', 'DAGS_FOLDER/test.py', '--cfg-path', '/tmp/tmpbgygkivp']
[2025-07-15T03:56:02.082+0000] {standard_task_runner.py:91} INFO - Job 2: Subtask one_time_setup_with_pre_execute
[2025-07-15T03:56:02.091+0000] {logging_mixin.py:188} WARNING - /home/***/.local/lib/python3.11/site-packages/***/settings.py:195 DeprecationWarning: The sql_alchemy_conn option in [core] has been moved to the sql_alchemy_conn option in [database] - the old setting has been used, but please update your config.
[2025-07-15T03:56:02.117+0000] {task_command.py:426} INFO - Running <TaskInstance: test_first_run_and_custom_date.one_time_setup_with_pre_execute scheduled__2025-07-11T17:00:00+00:00 [running]> on host bc01ce72dbd8
[2025-07-15T03:56:02.353+0000] {taskinstance.py:2648} INFO - Exporting env vars: AIRFLOW_CTX_DAG_OWNER='***' AIRFLOW_CTX_DAG_ID='test_first_run_and_custom_date' AIRFLOW_CTX_TASK_ID='one_time_setup_with_pre_execute' AIRFLOW_CTX_EXECUTION_DATE='2025-07-11T17:00:00+00:00' AIRFLOW_CTX_TRY_NUMBER='1' AIRFLOW_CTX_DAG_RUN_ID='scheduled__2025-07-11T17:00:00+00:00'
[2025-07-15T03:56:02.355+0000] {taskinstance.py:2905} ERROR - Task failed with exception
Traceback (most recent call last):
  File "/home/airflow/.local/lib/python3.11/site-packages/airflow/models/taskinstance.py", line 2479, in _run_raw_task
    self._execute_task_with_callbacks(context, test_mode, session=session)
  File "/home/airflow/.local/lib/python3.11/site-packages/airflow/models/taskinstance.py", line 2655, in _execute_task_with_callbacks
    self.task.pre_execute(context=context)  # type: ignore[union-attr]
    ^^^^^^^^^^^^^^^^^^^^^^^^^^^^^^^^^^^^^^
  File "/home/airflow/.local/lib/python3.11/site-packages/airflow/lineage/__init__.py", line 156, in wrapper
    return func(self, context, *args, **kwargs)
           ^^^^^^^^^^^^^^^^^^^^^^^^^^^^^^^^^^^^
  File "/home/airflow/.local/lib/python3.11/site-packages/airflow/models/baseoperator.py", line 1261, in pre_execute
    self._pre_execute_hook(context)
TypeError: check_if_first_run() takes 0 positional arguments but 1 was given
[2025-07-15T03:56:02.363+0000] {taskinstance.py:1206} INFO - Marking task as FAILED. dag_id=test_first_run_and_custom_date, task_id=one_time_setup_with_pre_execute, run_id=scheduled__2025-07-11T17:00:00+00:00, execution_date=20250711T170000, start_date=20250715T035602, end_date=20250715T035602
[2025-07-15T03:56:02.375+0000] {standard_task_runner.py:110} ERROR - Failed to execute job 2 for task one_time_setup_with_pre_execute (check_if_first_run() takes 0 positional arguments but 1 was given; 1165)
[2025-07-15T03:56:02.385+0000] {local_task_job_runner.py:240} INFO - Task exited with return code 1
[2025-07-15T03:56:02.402+0000] {taskinstance.py:3503} INFO - 1 downstream tasks scheduled from follow-on schedule check
[2025-07-15T03:56:02.406+0000] {local_task_job_runner.py:222} INFO - ::endgroup::
